#!/usr/bin/env python3# -*- coding: utf-8 -*-"""Created on 2017/6/2 下午5:25@author: zhechengma"""import pandas as pdfrom pandas import DataFrame,Seriesimport pymysqlfrom pandas.io.sql import to_sqlfrom sqlalchemy import create_engineconn=pymysql.connect(host='192.168.32.48',port=3306,user='root',password='123456',db='network',charset='utf8')con=pymysql.connect(host='192.168.32.48',port=3306,user='root',password='123456',db='miqixin',charset='utf8')df1=pd.read_sql('select * from c_base_info order by id desc limit 0,10',conn)engine=create_engine("mysql+pymysql://root:123456@192.168.32.48:3306/miqixin?charset=utf8")try:	df1.to_sql('c_base',con = engine,if_exists = 'append',index = True,index_label = None)except Exception as ee:	print(ee)	passdf2=pd.read_sql('select * from c_base order by id desc limit 0,10',con)print(df1.head(5))print('___________________')print(df2.head(5))